
这个脚本放在服务器执行，退出码就是0（即表示执行成功）。不过，Node.js 有一个unhandledRejection事件，专门监听未捕获的reject错误，上面的脚本会触发这个事件的监听函数，可以在监听函数里面抛出错误。

process.on('unhandledRejection', function (err, p) {
  throw err;
});
上面代码中，unhandledRejection事件的监听函数有两个参数，第一个是错误对象，第二个是报错的 Promise 实例，它可以用来了解发生错误的环境信息。

注意，Node 有计划在未来废除unhandledRejection事件。如果 Promise 内部有未捕获的错误，会直接终止进程，并且进程的退出码不为 0。
